<?xml version="1.0" encoding="utf-8"?>
<!-- =================================================================================== -->
<!-- |    This document was autogenerated by xacro from tx90.xacro                     | -->
<!-- |    EDITING THIS FILE BY HAND IS NOT RECOMMENDED                                 | -->
<!-- =================================================================================== -->
<robot name="staubli_tx90_gazebo">
  <!-- colours based on RAL values supplied by Staubli -->
  <!-- all RAL colours converted using http://www.visual-graphics.de/en/customer-care/ral-colours -->
  <!-- default colours for robots -->
  <!-- links: main serial chain -->
  <link name="base_link">
    <visual>
      <origin rpy="0 0 0" xyz="0 0 0"/>
      <geometry>
        <mesh filename="package://staubli_tx90_support/meshes/tx90/visual/base_link.stl"/>
      </geometry>
      <material name="">
        <color rgba="1.0 0.607843137255 0.0 1.0"/>
      </material>
    </visual>
    <collision>
      <origin rpy="0 0 0" xyz="0 0 0"/>
      <geometry>
        <mesh filename="package://staubli_tx90_support/meshes/tx90/collision/base_link.stl"/>
      </geometry>
    </collision>
    <inertial>
      <mass value="10.733459"/>
      <origin rpy="0.0 0.0 0.0" xyz="0.014288 0.000001 0.122264"/>
      <inertia ixx="0.096590" ixy="-0.000005" ixz="-0.003803" iyy="0.087591" iyz="-0.000001" izz="0.081632"/>
    </inertial>
  </link>
  <link name="link_1">
    <visual>
      <origin rpy="0 0 0" xyz="0 0 0"/>
      <geometry>
        <mesh filename="package://staubli_tx90_support/meshes/tx90/visual/link_1.stl"/>
      </geometry>
      <material name="">
        <color rgba="1.0 0.607843137255 0.0 1.0"/>
      </material>
    </visual>
    <collision>
      <origin rpy="0 0 0" xyz="0 0 0"/>
      <geometry>
        <mesh filename="package://staubli_tx90_support/meshes/tx90/collision/link_1.stl"/>
      </geometry>
    </collision>
    <inertial>
      <mass value="16.934564"/>
      <origin rpy="0.0 0.0 0.0" xyz="0.019143 0.024764 -0.064596"/>
      <inertia ixx="0.222318" ixy="0.016499" ixz="0.023794" iyy="0.208959" iyz="0.031663" izz="0.157081"/>
    </inertial>
  </link>
  <link name="link_2">
    <visual>
      <origin rpy="0 0 0" xyz="0 0 0"/>
      <geometry>
        <mesh filename="package://staubli_tx90_support/meshes/tx90/visual/link_2.stl"/>
      </geometry>
      <material name="">
        <color rgba="1.0 0.607843137255 0.0 1.0"/>
      </material>
    </visual>
    <collision>
      <origin rpy="0 0 0" xyz="0 0 0"/>
      <geometry>
        <mesh filename="package://staubli_tx90_support/meshes/tx90/collision/link_2.stl"/>
      </geometry>
    </collision>
    <inertial>
      <mass value="12.98711"/>
      <origin rpy="0.0 0.0 0.0" xyz="-0.000008 0.221181 0.173052"/>
      <inertia ixx="0.425299" ixy="0.000005" ixz="-0.000004" iyy="0.452311" iyz="-0.002920" izz="0.054493"/>
    </inertial>
  </link>
  <link name="link_3">
    <visual>
      <origin rpy="0 0 0" xyz="0 0 0"/>
      <geometry>
        <mesh filename="package://staubli_tx90_support/meshes/tx90/visual/link_3.stl"/>
      </geometry>
      <material name="">
        <color rgba="1.0 0.607843137255 0.0 1.0"/>
      </material>
    </visual>
    <collision>
      <origin rpy="0 0 0" xyz="0 0 0"/>
      <geometry>
        <mesh filename="package://staubli_tx90_support/meshes/tx90/collision/link_3.stl"/>
      </geometry>
    </collision>
    <inertial>
      <mass value="7.50151"/>
      <origin rpy="0.0 0.0 0.0" xyz="0.000002 0.065008 0.003572"/>
      <inertia ixx="0.058902" ixy="0.000000" ixz="0.000001" iyy="0.056884" iyz="-0.003672" izz="0.034271"/>
    </inertial>
  </link>
  <link name="link_4">
    <visual>
      <origin rpy="0 0 0" xyz="0 0 0"/>
      <geometry>
        <mesh filename="package://staubli_tx90_support/meshes/tx90/visual/link_4.stl"/>
      </geometry>
      <material name="">
        <color rgba="1.0 0.607843137255 0.0 1.0"/>
      </material>
    </visual>
    <collision>
      <origin rpy="0 0 0" xyz="0 0 0"/>
      <geometry>
        <mesh filename="package://staubli_tx90_support/meshes/tx90/collision/link_4.stl"/>
      </geometry>
    </collision>
    <inertial>
      <mass value="4.54015"/>
      <origin rpy="0.0 0.0 0.0" xyz="-0.002488 0.049988 0.296156"/>
      <inertia ixx="0.043246" ixy="0.000003" ixz="-0.000683" iyy="0.038394" iyz="-0.000004" izz="0.014525"/>
    </inertial>
  </link>
  <link name="link_5">
    <visual>
      <origin rpy="0 0 0" xyz="0 0 0"/>
      <geometry>
        <mesh filename="package://staubli_tx90_support/meshes/tx90/visual/link_5.stl"/>
      </geometry>
      <material name="">
        <color rgba="0.529411764706 0.521568627451 0.505882352941 1.0"/>
      </material>
    </visual>
    <collision>
      <origin rpy="0 0 0" xyz="0 0 0"/>
      <geometry>
        <mesh filename="package://staubli_tx90_support/meshes/tx90/collision/link_5.stl"/>
      </geometry>
    </collision>
    <inertial>
      <mass value="0.56876"/>
      <origin rpy="0.0 0.0 0.0" xyz="0.000000 0.049931 0.222823"/>
      <inertia ixx="0.001084" ixy="0.000000" ixz="0.000000" iyy="0.001123" iyz="0.000001" izz="0.000383"/>
    </inertial>
  </link>
  <link name="link_6">
    <visual>
      <origin rpy="0 0 0" xyz="0 0 0"/>
      <geometry>
        <mesh filename="package://staubli_tx90_support/meshes/tx90/visual/link_6.stl"/>
      </geometry>
      <material name="">
        <color rgba="0.529411764706 0.521568627451 0.505882352941 1.0"/>
      </material>
    </visual>
    <collision>
      <origin rpy="0 0 0" xyz="0 0 0"/>
      <geometry>
        <mesh filename="package://staubli_tx90_support/meshes/tx90/collision/link_6.stl"/>
      </geometry>
    </collision>
    <inertial>
      <mass value="0.03098"/>
      <origin rpy="0.0 0.0 0.0" xyz="-0.000243 0.050000 -0.006293"/>
      <inertia ixx="0.000012" ixy="0.000000" ixz="0.000000" iyy="0.000011" iyz="0.000000" izz="0.000022"/>
    </inertial>
  </link>
  <link name="tool_link">
    <visual>
      <origin rpy="0 -1.57079632679 3.14159265359" xyz="0 0 0.001"/>
      <geometry>
        <mesh filename="package://tx90_spindle/meshes/base_link.STL"/>
      </geometry>
      <material name="">
        <color rgba="0.75294 0.75294 0.75294 1"/>
      </material>
    </visual>
    <collision>
      <origin rpy="0 -1.57079632679 3.14159265359" xyz="0 0 0.005"/>
      <geometry>
        <mesh filename="package://tx90_spindle/meshes/base_link.STL"/>
      </geometry>
    </collision>
    <inertial>
      <mass value="0.00536"/>
      <origin rpy="0 0 0" xyz="0.071574 -1.664E-06 0.013015"/>
      <inertia ixx="0.000012" ixy="0.0000000" ixz="0.0000000" iyy="0.0013662" iyz="0.0000000" izz="0.00054605"/>
    </inertial>
  </link>
  <!-- joints: main serial chain -->
  <joint name="joint_1" type="revolute">
    <origin rpy="0 0 0" xyz="0 0 0.478"/>
    <parent link="base_link"/>
    <child link="link_1"/>
    <axis xyz="0 0 1"/>
    <!-- from Staubli instruction manual:
      (1) effort limit = 318 Nm if floor mounted
      (2) effort limit = 111 Nm if wall mounted -->
    <limit effort="318.0" lower="-3.14159265359" upper="3.14159265359" velocity="6.98131700798"/>
    <dynamics damping="0.0" friction="0.0"/>
  </joint>
  <joint name="joint_2" type="revolute">
    <origin rpy="0 0 0" xyz="0.050 0 0"/>
    <parent link="link_1"/>
    <child link="link_2"/>
    <axis xyz="0 1 0"/>
    <limit effort="166.0" lower="-2.26892802759" upper="2.57436064669" velocity="6.98131700798"/>
    <dynamics damping="0.0" friction="0.0"/>
  </joint>
  <joint name="joint_3" type="revolute">
    <origin rpy="0 0 0" xyz="0 0.05 0.425"/>
    <parent link="link_2"/>
    <child link="link_3"/>
    <axis xyz="0 1 0"/>
    <limit effort="76.0" lower="-2.53072741539" upper="2.53072741539" velocity="7.50491578358"/>
    <dynamics damping="0.0" friction="0.0"/>
  </joint>
  <joint name="joint_4" type="revolute">
    <origin rpy="0 0 0" xyz="0 0 0"/>
    <parent link="link_3"/>
    <child link="link_4"/>
    <axis xyz="0 0 1"/>
    <limit effort="34.0" lower="-4.71238898038" upper="4.71238898038" velocity="9.42477796077"/>
    <dynamics damping="0.0" friction="0.0"/>
  </joint>
  <joint name="joint_5" type="revolute">
    <origin rpy="0 0 0" xyz="0 0 0.425"/>
    <parent link="link_4"/>
    <child link="link_5"/>
    <axis xyz="0 1 0"/>
    <limit effort="29.0" lower="-2.00712863979" upper="2.44346095279" velocity="8.29031394697"/>
    <dynamics damping="0.0" friction="0.0"/>
  </joint>
  <joint name="joint_6" type="revolute">
    <origin rpy="0 0 0" xyz="0 0 0.100"/>
    <parent link="link_5"/>
    <child link="link_6"/>
    <axis xyz="0 0 1"/>
    <limit effort="11.0" lower="-4.71238898038" upper="4.71238898038" velocity="13.2645023152"/>
    <dynamics damping="0.0" friction="0.0"/>
  </joint>
  <!-- ROS-Industrial 'base' frame: base_link to Staubli World Coordinates transform -->
  <link name="base"/>
  <joint name="base_link-base" type="fixed">
    <origin rpy="0 0 0" xyz="0 0 0.478"/>
    <parent link="base_link"/>
    <child link="base"/>
    <axis xyz="0 0 0"/>
  </joint>
  <!-- ROS-Industrial 'flange' frame: attachment point for EEF models -->
  <link name="flange"/>
  <joint name="joint_6-flange" type="fixed">
    <origin rpy="0 -1.57079632679 0" xyz="0 0 0"/>
    <parent link="link_6"/>
    <child link="flange"/>
  </joint>
  <joint name="tool_link_fixed" type="fixed">
    <parent link="flange"/>
    <child link="tool_link"/>
    <origin rpy="0 1.57079632679 0" xyz="0 0 0"/>
  </joint>
  <!-- ROS-Industrial 'tool0' frame: all-zeros tool frame -->
  <link name="tool0"/>
  <joint name="flange-tool0" type="fixed">
    <origin rpy="0 0 0" xyz="0.191 0 0.1027"/>
    <parent link="tool_link"/>
    <child link="tool0"/>
  </joint>
  <material name="aluminum">
    <color rgba="0.5 0.5 0.5 1"/>
  </material>
  <material name="plastic">
    <color rgba="0.1 0.1 0.1 1"/>
  </material>
  <!-- camera body, with origin at bottom screw mount -->
  <!-- transmission list -->
  <transmission name="tran1">
    <robotNamespace>/</robotNamespace>
    <type>transmission_interface/SimpleTransmission</type>
    <joint name="joint_1">
      <hardwareInterface>hardware_interface/PositionJointInterface</hardwareInterface>
    </joint>
    <actuator name="motor1">
      <mechanicalReduction>1</mechanicalReduction>
    </actuator>
  </transmission>
  <transmission name="tran2">
    <robotNamespace>/</robotNamespace>
    <type>transmission_interface/SimpleTransmission</type>
    <joint name="joint_2">
      <hardwareInterface>hardware_interface/PositionJointInterface</hardwareInterface>
    </joint>
    <actuator name="motor2">
      <mechanicalReduction>1</mechanicalReduction>
    </actuator>
  </transmission>
  <transmission name="tran3">
    <robotNamespace>/</robotNamespace>
    <type>transmission_interface/SimpleTransmission</type>
    <joint name="joint_3">
      <hardwareInterface>hardware_interface/PositionJointInterface</hardwareInterface>
    </joint>
    <actuator name="motor3">
      <mechanicalReduction>1</mechanicalReduction>
    </actuator>
  </transmission>
  <transmission name="tran4">
    <robotNamespace>/</robotNamespace>
    <type>transmission_interface/SimpleTransmission</type>
    <joint name="joint_4">
      <hardwareInterface>hardware_interface/PositionJointInterface</hardwareInterface>
    </joint>
    <actuator name="motor4">
      <mechanicalReduction>1</mechanicalReduction>
    </actuator>
  </transmission>
  <transmission name="tran5">
    <robotNamespace>/</robotNamespace>
    <type>transmission_interface/SimpleTransmission</type>
    <joint name="joint_5">
      <hardwareInterface>hardware_interface/PositionJointInterface</hardwareInterface>
    </joint>
    <actuator name="motor5">
      <mechanicalReduction>1</mechanicalReduction>
    </actuator>
  </transmission>
  <transmission name="tran6">
    <robotNamespace>/</robotNamespace>
    <type>transmission_interface/SimpleTransmission</type>
    <joint name="joint_6">
      <hardwareInterface>hardware_interface/PositionJointInterface</hardwareInterface>
    </joint>
    <actuator name="motor6">
      <mechanicalReduction>1</mechanicalReduction>
    </actuator>
  </transmission>
  <!-- end of transmission list -->
  <!-- Gazebo-specific link properties -->
  <gazebo reference="base_link">
    <material>Gazebo/Yellow</material>
    <turnGravityOff>true</turnGravityOff>
  </gazebo>
  <gazebo reference="link_1">
    <material>Gazebo/Yellow</material>
    <turnGravityOff>true</turnGravityOff>
  </gazebo>
  <gazebo reference="link_2">
    <material>Gazebo/Yellow</material>
    <turnGravityOff>true</turnGravityOff>
  </gazebo>
  <gazebo reference="link_3">
    <material>Gazebo/Yellow</material>
    <turnGravityOff>true</turnGravityOff>
  </gazebo>
  <gazebo reference="link_4">
    <material>Gazebo/Yellow</material>
    <turnGravityOff>true</turnGravityOff>
  </gazebo>
  <gazebo reference="link_5">
    <material>Gazebo/Grey</material>
    <turnGravityOff>true</turnGravityOff>
  </gazebo>
  <gazebo reference="link_6">
    <material>Gazebo/Grey</material>
    <turnGravityOff>true</turnGravityOff>
  </gazebo>
  <gazebo reference="tool_link">
    <material>Gazebo/Grey</material>
    <turnGravityOff>true</turnGravityOff>
  </gazebo>
  <!-- ros_control plugin -->
  <!-- Fix robot to Gazebo world -->
  <link name="world"/>
  <joint name="world-base_link-fixed" type="fixed">
    <parent link="world"/>
    <child link="base_link"/>
    <origin rpy="0.0 0.0 0.0" xyz="0.0 0.0 0.0"/>
  </joint>
</robot>

